Workbook

Sheet 總表
A1: 項次 | B1: 小隊 | C1: 報名序號 | D1: 兒童姓名 | E1: 性別 | F1: 年級 | G1: 學校 | H1: 家長姓名 | I1: 家長行動電話 | J1: 備註
A2: 1 | B2: =IFERROR(INDEX(四年級!$B:$B,MATCH(D2,四年級!$D:$D,0)),"") -> S417 | C2: 尚未繳費 | D2: 黃敬耘 | E2: 男 | F2: 四年級 | G2: 民和國小 | H2: 呂惠加 | I2: 0986333249
A3: 2 | B3: =IFERROR(INDEX(一年級!$B:$B,MATCH(D3,一年級!$D:$D,0)),"") -> S107 | C3: 尚未繳費 | D3: 徐嘉佑 | E3: 男 | F3: 一年級 | G3: 復興國小 | H3: 徐育筠 | I3: 0905105149
A4: 3 | B4: =IFERROR(INDEX(一年級!$B:$B,MATCH(D4,一年級!$D:$D,0)),"") -> S107 | C4: 尚未繳費 | D4: 黃靖洧 | E4: 男 | F4: 一年級 | G4: 公館國小 | H4: 王碧的 | I4: 0981101342
A5: 4 | B5: =IFERROR(INDEX(學齡前!$B:$B,MATCH(D5,學齡前!$D:$D,0)),"") -> D002 | C5: 尚未繳費 | D5: 黃允恩 | E5: 男 | F5: 中班 | G5: 美金 | H5: 彭浩羽 | I5: 0978715445 | J5: 希望可以跟可蓉可澍同一個小隊
A6: 5 | B6: =IFERROR(INDEX(學齡前!$B:$B,MATCH(D6,學齡前!$D:$D,0)),"") -> D003 | C6: 尚未繳費 | D6: 吳俞萱 | E6: 女 | F6: 大班 | G6: 小魟魚幼稚園 | H6: 蔡敏真 | I6: 0963657598
A7: 6 | B7: =IFERROR(INDEX(一年級!$B:$B,MATCH(D7,一年級!$D:$D,0)),"") -> S107 | C7: 尚未繳費 | D7: 陳立恆 | E7: 男 | F7: 一年級 | G7: 九如國小 | H7: 施玉華 | I7: 0962002242
A8: 7 | B8: =IFERROR(INDEX(學齡前!$B:$B,MATCH(D8,學齡前!$D:$D,0)),"") -> D004 | C8: 尚未繳費 | D8: 陳品妍 | E8: 女 | F8: 大班 | G8: 育英幼兒園 | H8: 施玉華 | I8: 0962002242
A9: 8 | B9: =IFERROR(INDEX(三年級!$B:$B,MATCH(D9,三年級!$D:$D,0)),"") -> S314 | C9: 尚未繳費 | D9: 薛閔倫 | E9: 男 | F9: 三年級 | G9: 瑞光國小 | H9: 顏慈 | I9: 0987629751
A10: 9 | B10: =IFERROR(INDEX(一年級!$B:$B,MATCH(D10,一年級!$D:$D,0)),"") -> S107 | C10: 尚未繳費 | D10: 李允斌 | E10: 男 | F10: 一年級 | G10: 大成 | H10: 李圻宏 | I10: 0931353168
A11: 10 | B11: =IFERROR(INDEX(二年級!$B:$B,MATCH(D11,二年級!$D:$D,0)),"") -> S210 | C11: 尚未繳費 | D11: 邱彥綸 | E11: 男 | F11: 二年級 | G11: 豐田國小 | H11: 李秀芳 | I11: 0983255801
A12: 11 | B12: =IFERROR(INDEX(五年級!$B:$B,MATCH(D12,五年級!$D:$D,0)),"") -> S520 | C12: 尚未繳費 | D12: 邱亮瑜 | E12: 女 | F12: 五年級 | G12: 豐田國小 | H12: 李秀芳 | I12: 0983255801
A13: 12 | B13: =IFERROR(INDEX(學齡前!$B:$B,MATCH(D13,學齡前!$D:$D,0)),"") -> D002 | C13: 尚未繳費 | D13: 謝沅希 | E13: 女 | F13: 中班 | G13: 大社幼兒園 | H13: 謝瑩霖 | I13: 0928032789
A14: 13 | B14: =IFERROR(INDEX(六年級!$B:$B,MATCH(D14,六年級!$D:$D,0)),"") -> S622 | C14: 尚未繳費 | D14: 史威廉 | E14: 男 | F14: 六年級 | G14: 民和 | H14: 史碩薇 | I14: 0911991275
A15: 14 | B15: =IFERROR(INDEX(二年級!$B:$B,MATCH(D15,二年級!$D:$D,0)),"") -> S210 | C15: 尚未繳費 | D15: 史班哲明 | E15: 男 | F15: 二年級 | G15: 民和 | H15: 史碩薇 | I15: 0911991275
A16: 15 | B16: =IFERROR(INDEX(學齡前!$B:$B,MATCH(D16,學齡前!$D:$D,0)),"") -> D001 | C16: 尚未繳費 | D16: 盧瑄彤 | E16: 女 | F16: 小班 | G16: 大同國小附幼 | H16: 潘姸禎 | I16: 0963678287
A17: 16 | B17: =IFERROR(INDEX(學齡前!$B:$B,MATCH(D17,學齡前!$D:$D,0)),"") -> D001 | C17: 尚未繳費 | D17: 陳宇瀚 | E17: 男 | F17: 小班 | G17: 維多利亞幼兒園 | H17: 李宜靜 | I17: 0980521240
A18: 17 | B18: =IFERROR(INDEX(二年級!$B:$B,MATCH(D18,二年級!$D:$D,0)),"") -> S210 | C18: 尚未繳費 | D18: 曾楷甯 | E18: 女 | F18: 二年級 | G18: 豐田國小 | H18: 劉怡彣 | I18: 0915582669
A19: 18 | B19: =IFERROR(INDEX(學齡前!$B:$B,MATCH(D19,學齡前!$D:$D,0)),"") -> D002 | C19: 尚未繳費 | D19: 劉宣葳 | E19: 女 | F19: 中班 | G19: 學正幼兒園 | H19: 邱意茹 | I19: 0927690649
A20: 19 | B20: =IFERROR(INDEX(四年級!$B:$B,MATCH(D20,四年級!$D:$D,0)),"") -> S417 | C20: 尚未繳費 | D20: 胡軒萓 | E20: 女 | F20: 四年級 | G20: 和平國小 | H20: 蕭翔憶 | I20: 0934050640
A21: 20 | B21: =IFERROR(INDEX(二年級!$B:$B,MATCH(D21,二年級!$D:$D,0)),"") -> S210 | C21: 尚未繳費 | D21: 胡恩瑜 | E21: 女 | F21: 二年級 | G21: 和平國小 | H21: 蕭翔憶 | I21: 0934050640
A22: 21 | B22: =IFERROR(INDEX(四年級!$B:$B,MATCH(D22,四年級!$D:$D,0)),"") -> S417 | C22: 尚未繳費 | D22: 莊晴甯 | E22: 女 | F22: 四年級 | G22: 潮昇國小 | H22: 田蕙雯 | I22: 0938049773
A23: 22 | B23: =IFERROR(INDEX(四年級!$B:$B,MATCH(D23,四年級!$D:$D,0)),"") -> S417 | C23: 尚未繳費 | D23: 鍾予棋 | E23: 女 | F23: 四年級 | G23: 潮昇國小 | H23: 田蕙雯 | I23: 0938049773
A24: 23 | B24: =IFERROR(INDEX(二年級!$B:$B,MATCH(D24,二年級!$D:$D,0)),"") -> S210 | C24: 尚未繳費 | D24: 張勻傑 | E24: 男 | F24: 二年級 | G24: 中正國小 | H24: 林淑莉 | I24: 0986229217
A25: 24 | B25: =IFERROR(INDEX(四年級!$B:$B,MATCH(D25,四年級!$D:$D,0)),"") -> S417 | C25: 尚未繳費 | D25: 林宥均 | E25: 女 | F25: 四年級 | G25: 高雄文山國小 | H25: 黃靖雯 | I25: 0980388563
A26: 25 | B26: =IFERROR(INDEX(學齡前!$B:$B,MATCH(D26,學齡前!$D:$D,0)),"") -> D002 | C26: 尚未繳費 | D26: 李可美 | E26: 女 | F26: 中班 | G26: 美金幼兒園 | H26: 李麗君 | I26: 0938787150
A27: 26 | B27: =IFERROR(INDEX(三年級!$B:$B,MATCH(D27,三年級!$D:$D,0)),"") -> S314 | C27: 尚未繳費 | D27: 涂芳碩 | E27: 男 | F27: 三年級 | G27: 新圍國小 | H27: 王佳育 | I27: 0903235779
A28: 27 | B28: =IFERROR(INDEX(一年級!$B:$B,MATCH(D28,一年級!$D:$D,0)),"") -> S107 | C28: 尚未繳費 | D28: 涂恩熙 | E28: 男 | F28: 一年級 | G28: 新圍國小 | H28: 王佳育 | I28: 0903235779
A29: 28 | B29: =IFERROR(INDEX(二年級!$B:$B,MATCH(D29,二年級!$D:$D,0)),"") -> S210 | C29: 尚未繳費 | D29: 陳愉恩 | E29: 女 | F29: 二年級 | G29: 民和國小 | H29: 陳孟陽 | I29: 0926098287
A30: 29 | B30: =IFERROR(INDEX(二年級!$B:$B,MATCH(D30,二年級!$D:$D,0)),"") -> S210 | C30: 尚未繳費 | D30: 謝沐芩 | E30: 女 | F30: 二年級 | G30: 民和國小 | H30: 張巧樺 | I30: 0988031862
A31: 30 | B31: =IFERROR(INDEX(三年級!$B:$B,MATCH(D31,三年級!$D:$D,0)),"") -> S314 | C31: 尚未繳費 | D31: 陳佑慶 | E31: 男 | F31: 三年級 | G31: 公館國小 | H31: 李嘉容 | I31: 0976680986
A32: 31 | B32: =IFERROR(INDEX(學齡前!$B:$B,MATCH(D32,學齡前!$D:$D,0)),"") -> D002 | C32: 尚未繳費 | D32: 林恩槿 | E32: 女 | F32: 中班 | G32: 美金幼兒園 | H32: 孫珮珊 | I32: 0988209330
A33: 32 | B33: =IFERROR(INDEX(一年級!$B:$B,MATCH(D33,一年級!$D:$D,0)),"") -> S107 | C33: 尚未繳費 | D33: 林柏澔 | E33: 男 | F33: 一年級 | G33: 仁愛國小 | H33: 孫珮珊 | I33: 0988209330
A34: 33 | B34: =IFERROR(INDEX(二年級!$B:$B,MATCH(D34,二年級!$D:$D,0)),"") -> S210 | C34: 尚未繳費 | D34: 陳誼萱 | E34: 女 | F34: 二年級 | G34: 公館國小 | H34: 李嘉容 | I34: 0976680986
A35: 34 | B35: =IFERROR(INDEX(六年級!$B:$B,MATCH(D35,六年級!$D:$D,0)),"") -> S622 | C35: 001 | D35: 洪榮典 | E35: 男 | F35: 六年級 | G35: 勝利國小 | H35: 郭尹齡 | I35: 0919121400
A36: 35 | B36: =IFERROR(INDEX(學齡前!$B:$B,MATCH(D36,學齡前!$D:$D,0)),"") -> D004 | C36: 002 | D36: 蕭可蓉 | E36: 女 | F36: 大班 | G36: 大班 | H36: 鍾幸璉 | I36: 0911811127
A37: 36 | B37: =IFERROR(INDEX(學齡前!$B:$B,MATCH(D37,學齡前!$D:$D,0)),"") -> D001 | C37: 003 | D37: 蕭可澍 | E37: 男 | F37: 小班 | G37: 小班 | H37: 鍾幸璉 | I37: 0911811127 | J37: 跟蕭可蓉姐姐排在同一組，謝謝
A38: 37 | B38: =IFERROR(INDEX(三年級!$B:$B,MATCH(D38,三年級!$D:$D,0)),"") -> S314 | C38: 004 | D38: 張旭辰 | E38: 男 | F38: 三年級 | G38: 民和 | H38: 王玫瑜 | I38: 0987151634
A39: 38 | B39: =IFERROR(INDEX(三年級!$B:$B,MATCH(D39,三年級!$D:$D,0)),"") -> S314 | C39: 006 | D39: 翁煦宥 | E39: 男 | F39: 三年級 | G39: 大同國小 | H39: 翁梵偉 | I39: 0933684116
A40: 39 | B40: =IFERROR(INDEX(五年級!$B:$B,MATCH(D40,五年級!$D:$D,0)),"") -> S520 | C40: 007 | D40: 蔡侑宸 | E40: 男 | F40: 五年級 | G40: 公館 | H40: 林姵穎 | I40: 0981253528
...

Sheet 學齡前
A1: 項次 | B1: 小隊 | C1: 報名序號 | D1: 兒童姓名 | E1: 性別 | F1: 年級 | G1: 學校 | H1: 家長姓名 | I1: 家長行動電話 | J1: 備註
A2: 1 | B2: D001 | C2: 087 | D2: 趙睦然 | E2: 女 | F2: 未就學 | G2: 無 | H2: 李誌倩 | I2: 0919879432
A3: 2 | B3: D001 | C3: 226 | D3: 林牧羲 | E3: 男 | F3: 未就學 | G3: 無 | H3: 林亭君 | I3: 0913012350
A4: 3 | B4: D001 | C4: 228 | D4: 林牧堯 | E4: 男 | F4: 未就學 | G4: 無 | H4: 林亭君 | I4: 0913012350
A5: 4 | B5: D001 | C5: 尚未繳費 | D5: 盧瑄彤 | E5: 女 | F5: 小班 | G5: 大同國小附幼 | H5: 潘姸禎 | I5: 0963678287
A6: 5 | B6: D001 | C6: 尚未繳費 | D6: 陳宇瀚 | E6: 男 | F6: 小班 | G6: 維多利亞幼兒園 | H6: 李宜靜 | I6: 0980521240
A7: 6 | B7: D001 | C7: 003 | D7: 蕭可澍 | E7: 男 | F7: 小班 | G7: 小班 | H7: 鍾幸璉 | I7: 0911811127 | J7: 跟蕭可蓉姐姐排在同一組，謝謝
A8: 7 | B8: D001 | C8: 015 | D8: 吳軒 | E8: 男 | F8: 小班 | G8: 喬智幼兒園 | H8: 吳尚靜 | I8: 0989804214
A9: 8 | B9: D001 | C9: 026 | D9: 張慕恩 | E9: 男 | F9: 小班 | G9: 幼愛幼兒園 | H9: 蔡榆彤 | I9: 0963003941
A10: 9 | B10: D001 | C10: 041 | D10: 洪胤齊 | E10: 男 | F10: 小班 | G10: 小哈佛 | H10: 洪憶雯 | I10: 0956083673
A11: 10 | B11: D001 | C11: 070 | D11: 李知穎 | E11: 女 | F11: 小班 | G11: 道明 | H11: 李倩蓉 | I11: 0981216626
A12: 11 | B12: D001 | C12: 083 | D12: 鍾宇安 | E12: 男 | F12: 小班 | G12: 龍幼 | H12: 黃佳惠 | I12: 0938677852
A13: 12 | B13: D001 | C13: 088 | D13: 楊鎧婍 | E13: 女 | F13: 小班 | G13: 九如幼兒園 | H13: 莊薏靜 | I13: 0986032669
A14: 13 | B14: D002 | C14: 132 | D14: 施芮霏 | E14: 女 | F14: 小班 | G14: 維多莉亞 | H14: 翁卿郁 | I14: 0973573965
A15: 14 | B15: D002 | C15: 155 | D15: 陳禹璇 | E15: 女 | F15: 小班 | G15: 幼愛幼兒園 | H15: 李秀葳 | I15: 0916031767
A16: 15 | B16: D002 | C16: 尚未繳費 | D16: 黃允恩 | E16: 男 | F16: 中班 | G16: 美金 | H16: 彭浩羽 | I16: 0978715445 | J16: 希望可以跟可蓉可澍同一個小隊
A17: 16 | B17: D002 | C17: 尚未繳費 | D17: 謝沅希 | E17: 女 | F17: 中班 | G17: 大社幼兒園 | H17: 謝瑩霖 | I17: 0928032789
A18: 17 | B18: D002 | C18: 尚未繳費 | D18: 劉宣葳 | E18: 女 | F18: 中班 | G18: 學正幼兒園 | H18: 邱意茹 | I18: 0927690649
A19: 18 | B19: D002 | C19: 尚未繳費 | D19: 李可美 | E19: 女 | F19: 中班 | G19: 美金幼兒園 | H19: 李麗君 | I19: 0938787150
A20: 19 | B20: D002 | C20: 尚未繳費 | D20: 林恩槿 | E20: 女 | F20: 中班 | G20: 美金幼兒園 | H20: 孫珮珊 | I20: 0988209330
A21: 20 | B21: D002 | C21: 033 | D21: 山語沁 | E21: 男 | F21: 中班 | G21: 潮州鎮立幼兒園 | H21: 黃羿禎 | I21: 0966342393
A22: 21 | B22: D002 | C22: 038 | D22: 許凱宸 | E22: 男 | F22: 中班 | G22: 大同附幼 | H22: 黃于庭 | I22: 0927113520
A23: 22 | B23: D002 | C23: 039 | D23: 陳奕縉 | E23: 男 | F23: 中班 | G23: 道明 | H23: 樊家怡 | I23: 0972161068
A24: 23 | B24: D002 | C24: 042 | D24: 吳語喬 | E24: 女 | F24: 中班 | G24: 美加 | H24: 黃雙燕 | I24: 0915603795
A25: 24 | B25: D002 | C25: 045 | D25: 高愛 | E25: 女 | F25: 中班 | G25: 崇蘭國小 | H25: 林慧珊 | I25: 0989348974 | J25: 要跟可澍同一隊
A26: 25 | B26: D003 | C26: 057 | D26: 鄭宇喬 | E26: 女 | F26: 中班 | G26: 美加 | H26: 鄭毓優 | I26: 0980528098
A27: 26 | B27: D003 | C27: 059 | D27: 林莞宸 | E27: 女 | F27: 中班 | G27: 私立屏東培正幼兒園 | H27: 林姵君 | I27: 0960398399
A28: 27 | B28: D003 | C28: 060 | D28: 林莞夏 | E28: 女 | F28: 中班 | G28: 私立屏東培正幼兒園 | H28: 林姵君 | I28: 0960398399
A29: 28 | B29: D003 | C29: 064 | D29: 鄭丞淏 | E29: 男 | F29: 中班 | G29: 龍華幼兒園 | H29: 徐佳琪 | I29: 0938563805
A30: 29 | B30: D003 | C30: 068 | D30: 李杰恩 | E30: 男 | F30: 中班 | G30: 道明 | H30: 李倩蓉 | I30: 0981216626
A31: 30 | B31: D003 | C31: 069 | D31: 李哲宇 | E31: 男 | F31: 中班 | G31: 道明 | H31: 李倩蓉 | I31: 0981216626
A32: 31 | B32: D003 | C32: 074 | D32: 陳語涵 | E32: 女 | F32: 中班 | G32: 小哈佛 | H32: 鍾珮如 | I32: 0981150582
A33: 32 | B33: D003 | C33: 082 | D33: 鍾宇昌 | E33: 男 | F33: 中班 | G33: 龍幼 | H33: 黃佳惠 | I33: 0938677852
A34: 33 | B34: D003 | C34: 094 | D34: 邱苡棠 | E34: 女 | F34: 中班 | G34: 建國附幼 | H34: 林家榛 | I34: 0983666783
A35: 34 | B35: D003 | C35: 104 | D35: 張睿家 | E35: 男 | F35: 中班 | G35: 大同 | H35: 洪雅婷 | I35: 0925999304
A36: 35 | B36: D003 | C36: 118 | D36: 涂芸榛 | E36: 女 | F36: 中班 | G36: 國稅局教保中心 | H36: 涂志豪 | I36: 0971668233
A37: 36 | B37: D003 | C37: 130 | D37: 黃乙晏 | E37: 女 | F37: 中班 | G37: 喬智 | H37: 李依蓉 | I37: 0910390799
... A63: 62 | B63: D005 | C63: 114 | D63: 蘇宥榛 | E63: 女 | F63: 大班 | G63: 萬丹附幼 | H63: 陳惠慈 | I63: 0955134115
A64: 63 | B64: D005 | C64: 131 | D64: 蕭雨芯 | E64: 女 | F64: 大班 | G64: 無 | H64: 蕭蕙萍 | I64: 0911181212 | J64: 10/26 來電表示：預計11/1-11/2前來繳費（瑜雯留）
A65: 64 | B65: D005 | C65: 134 | D65: 林言哲 | E65: 男 | F65: 大班 | G65: 復興非營利幼兒園 | H65: 黃郁庭 | I65: 0938537633
...

Sheet 一年級
A1: 項次 | B1: 小隊 | C1: 報名序號 | D1: 兒童姓名 | E1: 性別 | F1: 年級 | G1: 學校 | H1: 家長姓名 | I1: 家長行動電話 | J1: 備註
A2: 1 | B2: S107 | C2: 尚未繳費 | D2: 徐嘉佑 | E2: 男 | F2: 一年級 | G2: 復興國小 | H2: 徐育筠 | I2: 0905105149
A3: 2 | B3: S107 | C3: 尚未繳費 | D3: 黃靖洧 | E3: 男 | F3: 一年級 | G3: 公館國小 | H3: 王碧的 | I3: 0981101342
A4: 3 | B4: S107 | C4: 尚未繳費 | D4: 陳立恆 | E4: 男 | F4: 一年級 | G4: 九如國小 | H4: 施玉華 | I4: 0962002242
A5: 4 | B5: S107 | C5: 尚未繳費 | D5: 李允斌 | E5: 男 | F5: 一年級 | G5: 大成 | H5: 李圻宏 | I5: 0931353168
A6: 5 | B6: S107 | C6: 尚未繳費 | D6: 涂恩熙 | E6: 男 | F6: 一年級 | G6: 新圍國小 | H6: 王佳育 | I6: 0903235779
A7: 6 | B7: S107 | C7: 尚未繳費 | D7: 林柏澔 | E7: 男 | F7: 一年級 | G7: 仁愛國小 | H7: 孫珮珊 | I7: 0988209330
A8: 7 | B8: S107 | C8: 010 | D8: 盧婷鈺 | E8: 女 | F8: 一年級 | G8: 崇蘭國小 | H8: 盧慧萍 | I8: 0968139955
A9: 8 | B9: S107 | C9: 014 | D9: 林忻儀 | E9: 女 | F9: 一年級 | G9: 瑞光國小 | H9: 陳芊榆 | I9: 0981111559
A10: 9 | B10: S107 | C10: 050 | D10: 顏寧悅 | E10: 女 | F10: 一年級 | G10: 崇蘭 | H10: 劉美辰 | I10: 0926387370
A11: 10 | B11: S107 | C11: 055 | D11: 徐子芮 | E11: 女 | F11: 一年級 | G11: 麟洛國小 | H11: 徐慶仁 | I11: 0955874956
A12: 11 | B12: S107 | C12: 061 | D12: 趙語曦 | E12: 女 | F12: 一年級 | G12: 崇蘭國小 | H12: 吳玟璇 | I12: 0939523219
A13: 12 | B13: S107 | C13: 067 | D13: 劉奕輝 | E13: 男 | F13: 一年級 | G13: 崇蘭國小 | H13: 陳靜媛 | I13: 0919124456
... A40: 39 | B40: S109 | C40: 247 | D40: 黃郁媗 | E40: 女 | F40: 一年級 | G40: 公館國小 | H40: 洪佩親 | I40: 0901413462

Sheet 二年級
A1: 項次 | B1: 小隊 | C1: 報名序號 | D1: 兒童姓名 | E1: 性別 | F1: 年級 | G1: 學校 | H1: 家長姓名 | I1: 家長行動電話 | J1: 備註
A2: 1 | B2: S210 | C2: 尚未繳費 | D2: 邱彥綸 | E2: 男 | F2: 二年級 | G2: 豐田國小 | H2: 李秀芳 | I2: 0983255801
A3: 2 | B3: S210 | C3: 尚未繳費 | D3: 史班哲明 | E3: 男 | F3: 二年級 | G3: 民和 | H3: 史碩薇 | I3: 0911991275
A4: 3 | B4: S210 | C4: 尚未繳費 | D4: 曾楷甯 | E4: 女 | F4: 二年級 | G4: 豐田國小 | H4: 劉怡彣 | I4: 0915582669
A5: 4 | B5: S210 | C5: 尚未繳費 | D5: 胡恩瑜 | E5: 女 | F5: 二年級 | G5: 和平國小 | H5: 蕭翔憶 | I5: 0934050640
A6: 5 | B6: S210 | C6: 尚未繳費 | D6: 張勻傑 | E6: 男 | F6: 二年級 | G6: 中正國小 | H6: 林淑莉 | I6: 0986229217
A7: 6 | B7: S210 | C7: 尚未繳費 | D7: 陳愉恩 | E7: 女 | F7: 二年級 | G7: 民和國小 | H7: 陳孟陽 | I7: 0926098287
A8: 7 | B8: S210 | C8: 尚未繳費 | D8: 謝沐芩 | E8: 女 | F8: 二年級 | G8: 民和國小 | H8: 張巧樺 | I8: 0988031862
A9: 8 | B9: S210 | C9: 尚未繳費 | D9: 陳誼萱 | E9: 女 | F9: 二年級 | G9: 公館國小 | H9: 李嘉容 | I9: 0976680986
A10: 9 | B10: S210 | C10: 017 | D10: 賴柏愷 | E10: 男 | F10: 二年級 | G10: 麟洛國小 | H10: 邱惠靖 | I10: 0989315584
A11: 10 | B11: S210 | C11: 024 | D11: 許雯茜 | E11: 女 | F11: 二年級 | G11: 瓦磘 | H11: 沈書帆 | I11: 0907094477
A12: 11 | B12: S210 | C12: 028 | D12: 徐晨心 | E12: 女 | F12: 二年級 | G12: 屏科實中國小部 | H12: 顏上慈 | I12: 0923628545
A13: 12 | B13: S210 | C13: 030 | D13: 王芷伶 | E13: 女 | F13: 二年級 | G13: 東興國小 | H13: 蘇婉菱 | I13: 0933633915
... A48: 47 | B48: S213 | C48: 244 | D48: 姚惠紜 | E48: 女 | F48: 二年級 | G48: 瑞光國小 | H48: 姚明辰 | I48: 0989147770

Sheet 三年級
A1: 項次 | B1: 小隊 | C1: 報名序號 | D1: 兒童姓名 | E1: 性別 | F1: 年級 | G1: 學校 | H1: 家長姓名 | I1: 家長行動電話 | J1: 備註
A2: 1 | B2: S314 | C2: 尚未繳費 | D2: 薛閔倫 | E2: 男 | F2: 三年級 | G2: 瑞光國小 | H2: 顏慈 | I2: 0987629751
A3: 2 | B3: S314 | C3: 尚未繳費 | D3: 涂芳碩 | E3: 男 | F3: 三年級 | G3: 新圍國小 | H3: 王佳育 | I3: 0903235779
A4: 3 | B4: S314 | C4: 尚未繳費 | D4: 陳佑慶 | E4: 男 | F4: 三年級 | G4: 公館國小 | H4: 李嘉容 | I4: 0976680986
A5: 4 | B5: S314 | C5: 004 | D5: 張旭辰 | E5: 男 | F5: 三年級 | G5: 民和 | H5: 王玫瑜 | I5: 0987151634
A6: 5 | B6: S314 | C6: 006 | D6: 翁煦宥 | E6: 男 | F6: 三年級 | G6: 大同國小 | H6: 翁梵偉 | I6: 0933684116
A7: 6 | B7: S314 | C7: 009 | D7: 盧宗晟 | E7: 男 | F7: 三年級 | G7: 崇蘭國小 | H7: 盧慧萍 | I7: 0968139955
A8: 7 | B8: S314 | C8: 018 | D8: 陳加宸 | E8: 男 | F8: 三年級 | G8: 麟洛國小 | H8: 賴玉梅 | I8: 0917669683
A9: 8 | B9: S314 | C9: 021 | D9: 溫新 | E9: 男 | F9: 三年級 | G9: 建國國小 | H9: 傅佩真 | I9: 0953871262
A10: 9 | B10: S314 | C10: 022 | D10: 溫河 | E10: 男 | F10: 三年級 | G10: 建國國小 | H10: 傅佩真 | I10: 0953871262
A11: 10 | B11: S314 | C11: 029 | D11: 徐晨睿 | E11: 男 | F11: 三年級 | G11: 屏科實中國小部 | H11: 顏上慈 | I11: 0923628545
A12: 11 | B12: S314 | C12: 035 | D12: 洪浚睿 | E12: 男 | F12: 三年級 | G12: 和平國小 | H12: 何珮瑜 | I12: 0982787014
A13: 12 | B13: S314 | C13: 044 | D13: 高樂 | E13: 男 | F13: 三年級 | G13: 崇蘭國小 | H13: 林慧珊 | I13: 0989348974
A14: 13 | B14: S315 | C14: 049 | D14: 顏琬悅 | E14: 女 | F14: 三年級 | G14: 崇蘭國小 | H14: 劉美辰 | I14: 0926387370 | J14: 與高樂同一隊
A15: 14 | B15: S315 | C15: 099 | D15: 陳治勳 | E15: 男 | F15: 三年級 | G15: 建國 | H15: 林瑜蔚 | I15: 0920897187
A16: 15 | B16: S315 | C16: 105 | D16: 張睿宇 | E16: 男 | F16: 三年級 | G16: 勝利國小 | H16: 洪雅婷 | I16: 0925999304
A17: 16 | B17: S315 | C17: 109 | D17: 陳政綸 | E17: 男 | F17: 三年級 | G17: 里港國小 | H17: 丁文婷 | I17: 0930120060
A18: 17 | B18: S315 | C18: 110 | D18: 鄒語涵 | E18: 女 | F18: 三年級 | G18: 竹田國小 | H18: 丁文雅 | I18: 0928490454
A19: 18 | B19: S315 | C19: 115 | D19: 陳立勳 | E19: 男 | F19: 三年級 | G19: 里港國小 | H19: 黃音瑜 | I19: 0917265161
A20: 19 | B20: S315 | C20: 121 | D20: 陳姵璇 | E20: 女 | F20: 三年級 | G20: 復興國小 | H20: 謝美玲 | I20: 0921246907
A21: 20 | B21: S315 | C21: 126 | D21: 邱薏心 | E21: 女 | F21: 三年級 | G21: 光春國小 | H21: 陳雅文 | I21: 0933620521
A22: 21 | B22: S315 | C22: 145 | D22: 柯羽桓 | E22: 男 | F22: 三年級 | G22: 新南國小 | H22: 黃培珊 | I22: 0989424773
A23: 22 | B23: S315 | C23: 146 | D23: 江依玹 | E23: 女 | F23: 三年級 | G23: 麟洛國小 | H23: 郭美翎 | I23: 0934152395
A24: 23 | B24: S315 | C24: 149 | D24: 黃芯棠 | E24: 女 | F24: 三年級 | G24: 南陽國小 | H24: 黃于庭 | I24: 0927113520
A25: 24 | B25: S315 | C25: 169 | D25: 徐晨曦 | E25: 男 | F25: 三年級 | G25: 中正國小 | H25: 吳彥慧 | I25: 0989068691
A26: 25 | B26: S316 | C26: 173 | D26: 曾苡晴 | E26: 女 | F26: 三年級 | G26: 勝利國小 | H26: 蔡佳君 | I26: 0910841544
... A30: 29 | B30: S316 | C30: 195 | D30: 陳祉涵 | E30: 女 | F30: 三年級 | G30: 和平 | H30: 林綉蓮 | I30: 0930050055
A31: 30 | B31: S316 | C31: 205 | D31: 鄭惠文 | E31: 女 | F31: 三年級 | G31: 三和國小 | I31: 0987001187
A32: 31 | B32: S316 | C32: 210 | D32: 藍振榮 | E32: 男 | F32: 三年級 | G32: 豐田國小 | H32: 藍秉琮 | I32: 0920502513
A33: 32 | B33: S316 | C33: 230 | D33: 李佩芹 | E33: 女 | F33: 三年級 | G33: 大同國小 | H33: 李朝陽 | I33: 0935437473
A34: 33 | B34: S316 | C34: 241 | D34: 陳竑旭 | E34: 男 | F34: 三年級 | G34: 崇蘭國小 | H34: 陳聖宗 | I34: 0980896350

Sheet 四年級
A1: 項次 | B1: 小隊 | C1: 報名序號 | D1: 兒童姓名 | E1: 性別 | F1: 年級 | G1: 學校 | H1: 家長姓名 | I1: 家長行動電話 | J1: 備註
A2: 1 | B2: S417 | C2: 尚未繳費 | D2: 黃敬耘 | E2: 男 | F2: 四年級 | G2: 民和國小 | H2: 呂惠加 | I2: 0986333249
A3: 2 | B3: S417 | C3: 尚未繳費 | D3: 胡軒萓 | E3: 女 | F3: 四年級 | G3: 和平國小 | H3: 蕭翔憶 | I3: 0934050640
A4: 3 | B4: S417 | C4: 尚未繳費 | D4: 莊晴甯 | E4: 女 | F4: 四年級 | G4: 潮昇國小 | H4: 田蕙雯 | I4: 0938049773
A5: 4 | B5: S417 | C5: 尚未繳費 | D5: 鍾予棋 | E5: 女 | F5: 四年級 | G5: 潮昇國小 | H5: 田蕙雯 | I5: 0938049773
A6: 5 | B6: S417 | C6: 尚未繳費 | D6: 林宥均 | E6: 女 | F6: 四年級 | G6: 高雄文山國小 | H6: 黃靖雯 | I6: 0980388563
A7: 6 | B7: S417 | C7: 025 | D7: 許雅涵 | E7: 女 | F7: 四年級 | G7: 瓦磘 | H7: 沈書帆 | I7: 0907094477
A8: 7 | B8: S417 | C8: 047 | D8: 鄭暐勳 | E8: 男 | F8: 四年級 | G8: 崇蘭國小 | H8: 林杉 | I8: 0976220378 | J8: 要跟高樂同隊
A9: 8 | B9: S417 | C9: 051 | D9: 陳琦恩 | E9: 女 | F9: 四年級 | G9: 和平國小 | H9: 黃雅慧 | I9: 0977234604 | J9: 要跟高愛同一隊
A10: 9 | B10: S417 | C10: 054 | D10: 蕭正得 | E10: 男 | F10: 四年級 | G10: 中正國小 | H10: 黃怡禎 | I10: 0916011129
A11: 10 | B11: S417 | C11: 056 | D11: 徐可芯 | E11: 女 | F11: 四年級 | G11: 麟洛國小 | H11: 徐慶仁 | I11: 0955874956
A12: 11 | B12: S417 | C12: 084 | D12: 王敦右 | E12: 男 | F12: 四年級 | G12: 公館國小 | H12: 孫韻甯 | I12: 0989778585
A13: 12 | B13: S417 | C13: 101 | D13: 簡家晨 | E13: 男 | F13: 四年級 | G13: 崇蘭國小 | H13: 周婉婷 | I13: 0989255110
A14: 13 | B14: S418 | C14: 107 | D14: 陳詠晴 | E14: 女 | F14: 四年級 | G14: 崇蘭國小 | H14: 陳雯雯 | I14: 0970645045
A15: 14 | B15: S418 | C15: 108 | D15: 陳芸莉 | E15: 女 | F15: 四年級 | G15: 里港國小 | H15: 丁文婷 | I15: 0930120060
A16: 15 | B16: S418 | C16: 127 | D16: 邱薏庭 | E16: 女 | F16: 四年級 | G16: 光春國小 | H16: 陳雅文 | I16: 0933620521
A17: 16 | B17: S418 | C17: 138 | D17: 彭盈萁 | E17: 女 | F17: 四年級 | G17: 民和國小 | H17: 陳宥澐 | I17: 0937987159
A18: 17 | B18: S418 | C18: 152 | D18: 鍾佳蓉 | E18: 女 | F18: 四年級 | G18: 長興國小 | H18: 吳蕙如 | I18: 0955769065
A19: 18 | B19: S418 | C19: 157 | D19: 陳以芯 | E19: 女 | F19: 四年級 | G19: 高雄信義國小 | H19: 林俊秀 | I19: 0919639392
A20: 19 | B20: S418 | C20: 159 | D20: 劉昕晴 | E20: 女 | F20: 四年級 | G20: 勝利國小 | H20: 陳姿帆 | I20: 0987368175
A21: 20 | B21: S418 | C21: 162 | D21: 謝羿辰 | E21: 男 | F21: 四年級 | G21: 民和 | H21: 劉淑芳 | I21: 0985368067
... A31: 30 | B31: S419 | C31: 238 | D31: 黃愃媮 | E31: 女 | F31: 四年級 | G31: 中正國小 | H31: 徐佳鈴 | I31: 0925111407

Sheet 五年級
A1: 項次 | B1: 小隊 | C1: 報名序號 | D1: 兒童姓名 | E1: 性別 | F1: 年級 | G1: 學校 | H1: 家長姓名 | I1: 家長行動電話 | J1: 備註
A2: 1 | B2: S520 | C2: 尚未繳費 | D2: 邱亮瑜 | E2: 女 | F2: 五年級 | G2: 豐田國小 | H2: 李秀芳 | I2: 0983255801
A3: 2 | B3: S520 | C3: 007 | D3: 蔡侑宸 | E3: 男 | F3: 五年級 | G3: 公館 | H3: 林姵穎 | I3: 0981253528
A4: 3 | B4: S520 | C4: 034 | D4: 郭凱森 | E4: 男 | F4: 五年級 | G4: 中正國小 | H4: 林盈吟 | I4: 0929062826
A5: 4 | B5: S520 | C5: 043 | D5: 高心 | E5: 女 | F5: 五年級 | G5: 崇蘭國小 | H5: 林慧珊 | I5: 0989348974
A6: 5 | B6: S520 | C6: 046 | D6: 鄭詩縈 | E6: 女 | F6: 五年級 | G6: 崇蘭國小 | H6: 林杉 | I6: 0976220378 | J6: 要跟高心同隊
A7: 6 | B7: S520 | C7: 080 | D7: 陳可芯 | E7: 女 | F7: 五年級 | G7: 和平國小 | H7: 蔡靜玲 | I7: 0925176902
A8: 7 | B8: S520 | C8: 116 | D8: 陳立恩 | E8: 男 | F8: 五年級 | G8: 里港國小 | H8: 黃音瑜 | I8: 0917265161
A9: 8 | B9: S520 | C9: 117 | D9: 陳宣諠 | E9: 女 | F9: 五年級 | G9: 民權國小 | H9: 黃音瑜 | I9: 0917265161
A10: 9 | B10: S520 | C10: 120 | D10: 陳貞 | E10: 女 | F10: 五年級 | G10: 復興國小 | H10: 蔡宜璇 | I10: 0929921789
A11: 10 | B11: S520 | C11: 140 | D11: 陳姵㚬 | E11: 女 | F11: 五年級 | G11: 民和 | H11: 邱郁涵 | I11: 0981802148
A12: 11 | B12: S521 | C12: 143 | D12: 資雨蒔 | E12: 女 | F12: 五年級 | G12: 勝利國小 | H12: 資義生 | I12: 0906559449
A13: 12 | B13: S521 | C13: 160 | D13: 劉昕宇 | E13: 男 | F13: 五年級 | G13: 勝利國小 | H13: 陳姿帆 | I13: 0987368172
A14: 13 | B14: S521 | C14: 164 | D14: 白詠箴 | E14: 女 | F14: 五年級 | G14: 長興 | H14: 梁慧嫺 | I14: 0981006091
A15: 14 | B15: S521 | C15: 168 | D15: 許庭榛 | E15: 女 | F15: 五年級 | G15: 東寧國小 | H15: 魏芳 | I15: 0916315399
A16: 15 | B16: S521 | C16: 185 | D16: 傅雨箴 | E16: 女 | F16: 五年級 | G16: 彭厝國小 | H16: 辜惠文 | I16: 0927683692
A17: 16 | B17: S521 | C17: 190 | D17: 利咏倫 | E17: 男 | F17: 五年級 | G17: 屏科實小 | H17: 陳儀芳 | I17: 0972896881
A18: 17 | B18: S521 | C18: 203 | D18: 黃羿瑄 | E18: 女 | F18: 五年級 | G18: 彭厝國小 | H18: 鄭喬云 | I18: 0925525015
... A20: 19 | B20: S521 | C20: 239 | D20: 黃暄喬 | E20: 女 | F20: 五年級 | G20: 中正國小 | H20: 徐佳鈴 | I20: 0925111407

Sheet 六年級
A1: 項次 | B1: 小隊 | C1: 報名序號 | D1: 兒童姓名 | E1: 性別 | F1: 年級 | G1: 學校 | H1: 家長姓名 | I1: 家長行動電話 | J1: 備註
A2: 1 | B2: S622 | C2: 尚未繳費 | D2: 史威廉 | E2: 男 | F2: 六年級 | G2: 民和 | H2: 史碩薇 | I2: 0911991275
A3: 2 | B3: S622 | C3: 001 | D3: 洪榮典 | E3: 男 | F3: 六年級 | G3: 勝利國小 | H3: 郭尹齡 | I3: 0919121400
A4: 3 | B4: S622 | C4: 016 | D4: 龍宥廷 | E4: 男 | F4: 六年級 | G4: 里港國小 | H4: 吳尚靜 | I4: 0989804214
A5: 4 | B5: S622 | C5: 053 | D5: 蕭亦圻 | E5: 女 | F5: 六年級 | G5: 中正國小 | H5: 黃怡禎 | I5: 0916011129
A6: 5 | B6: S622 | C6: 062 | D6: 陳詠晴（姊） | E6: 女 | F6: 六年級 | G6: 中正國小 | H6: 薛侑倫 | I6: 0975520550
A7: 6 | B7: S622 | C7: 072 | D7: 林道維 | E7: 男 | F7: 六年級 | G7: 和平國小 | H7: 林明龍 | I7: 0925199315
A8: 7 | B8: S622 | C8: 093 | D8: 郭宥鑫 | E8: 男 | F8: 六年級 | G8: 民和 | H8: 曾小娟 | I8: 0912799997
A9: 8 | B9: S623 | C9: 156 | D9: 陳以安 | E9: 男 | F9: 六年級 | G9: 高雄信義國小 | H9: 林俊秀 | I9: 9196939392
A10: 9 | B10: S623 | C10: 175 | D10: 陳子淵 | E10: 男 | F10: 六年級 | G10: 中正國小 | H10: 卓慧芳 | I10: 0977335115
A11: 10 | B11: S623 | C11: 177 | D11: 霍子宸 | E11: 男 | F11: 六年級 | G11: 中正國小 | H11: 葉逸君 | I11: 0931826532
A12: 11 | B12: S623 | C12: 189 | D12: 利卉喬 | E12: 女 | F12: 六年級 | G12: 屏科實小 | H12: 陳儀芳 | I12: 0972896881
A13: 12 | B13: S623 | C13: 198 | D13: 鍾宥晴 | E13: 男 | F13: 六年級 | G13: 屏東市中正國小 | H13: 鍾尚義 | I13: 0911880071
... A16: 15 | B16: S623 | C16: 235 | D16: 吳羿萱 | E16: 女 | F16: 六年級 | G16: 中正國小 | H16: 魏子菱 | I16: 0925723939
